data/sample/df_level2.csv
time,status,pre_close,open,high,low,last,ap1,ap2,ap3,ap4,ap5,ap6,ap7,ap8,ap9,ap10,av1,av2,av3,av4,av5,av6,av7,av8,av9,av10,bp1,bp2,bp3,bp4,bp5,bp6,bp7,bp8,bp9,bp10,bv1,bv2,bv3,bv4,bv5,bv6,bv7,bv8,bv9,bv10,num_trades,volume,amount,total_bid_vol,total_ask_vol,weighted_avg_bid_price,weighted_avg_ask_price,iopv,yield_to_maturity,high_limited,low_limited,prefix,syl1,syl2,sd2,trading_phase_code,pre_iopv,symbol,date
84501000,0,2.351,0.0,0.0,0.0,0.0,0.0,0.0,0.0,0.0,0.0,0.0,0.0,0.0,0.0,0.0,0,0,0,0,0,0,0,0,0,0,0.0,0.0,0.0,0.0,0.0,0.0,0.0,0.0,0.0,0.0,0,0,0,0,0,0,0,0,0,0,0,0,0.0,0,0,0.0,0.0,0.0,0,2.586,2.116,b'',0,0,0,b'S 10',0.0,SH.510050,20240207
84504000,0,2.351,0.0,0.0,0.0,0.0,0.0,0.0,0.0,0.0,0.0,0.0,0.0,0.0,0.0,0.0,0,0,0,0,0,0,0,0,0,0,0.0,0.0,0.0,0.0,0.0,0.0,0.0,0.0,0.0,0.0,0,0,0,0,0,0,0,0,0,0,0,0,0.0,0,0,0.0,0.0,0.0,0,2.586,2.116,b'',0,0,0,b'S 10',0.0,SH.510050,20240207
84507000,0,2.351,0.0,0.0,0.0,0.0,0.0,0.0,0.0,0.0,0.0,0.0,0.0,0.0,0.0,0.0,0,0,0,0,0,0,0,0,0,0,0.0,0.0,0.0,0.0,0.0,0.0,0.0,0.0,0.0,0.0,0,0,0,0,0,0,0,0,0,0,0,0,0.0,0,0,0.0,0.0,0.0,0,2.586,2.116,b'',0,0,0,b'S 10',0.0,SH.510050,20240207
84510000,0,2.351,0.0,0.0,0.0,0.0,0.0,0.0,0.0,0.0,0.0,0.0,0.0,0.0,0.0,0.0,0,0,0,0,0,0,0,0,0,0,0.0,0.0,0.0,0.0,0.0,0.0,0.0,0.0,0.0,0.0,0,0,0,0,0,0,0,0,0,0,0,0,0.0,0,0,0.0,0.0,0.0,0,2.586,2.116,b'',0,0,0,b'S 10',0.0,SH.510050,20240207
84513000,0,2.351,0.0,0.0,0.0,0.0,0.0,0.0,0.0,0.0,0.0,0.0,0.0,0.0,0.0,0.0,0,0,0,0,0,0,0,0,0,0,0.0,0.0,0.0,0.0,0.0,0.0,0.0,0.0,0.0,0.0,0,0,0,0,0,0,0,0,0,0,0,0,0.0,0,0,0.0,0.0,0.0,0,2.586,2.116,b'',0,0,0,b'S 10',0.0,SH.510050,20240207
84516000,0,2.351,0.0,0.0,0.0,0.0,0.0,0.0,0.0,0.0,0.0,0.0,0.0,0.0,0.0,0.0,0,0,0,0,0,0,0,0,0,0,0.0,0.0,0.0,0.0,0.0,0.0,0.0,0.0,0.0,0.0,0,0,0,0,0,0,0,0,0,0,0,0,0.0,0,0,0.0,0.0,0.0,0,2.586,2.116,b'',0,0,0,b'S 10',0.0,SH.510050,20240207
84519000,0,2.351,0.0,0.0,0.0,0.0,0.0,0.0,0.0,0.0,0.0,0.0,0.0,0.0,0.0,0.0,0,0,0,0,0,0,0,0,0,0,0.0,0.0,0.0,0.0,0.0,0.0,0.0,0.0,0.0,0.0,0,0,0,0,0,0,0,0,0,0,0,0,0.0,0,0,0.0,0.0,0.0,0,2.586,2.116,b'',0,0,0,b'S 10',0.0,SH.510050,20240207
84522000,0,2.351,0.0,0.0,0.0,0.0,0.0,0.0,0.0,0.0,0.0,0.0,0.0,0.0,0.0,0.0,0,0,0,0,0,0,0,0,0,0,0.0,0.0,0.0,0.0,0.0,0.0,0.0,0.0,0.0,0.0,0,0,0,0,0,0,0,0,0,0,0,0,0.0,0,0,0.0,0.0,0.0,0,2.586,2.116,b'',0,0,0,b'S 10',0.0,SH.510050,20240207
84525000,0,2.351,0.0,0.0,0.0,0.0,0.0,0.0,0.0,0.0,0.0,0.0,0.0,0.0,0.0,0.0,0,0,0,0,0,0,0,0,0,0,0.0,0.0,0.0,0.0,0.0,0.0,0.0,0.0,0.0,0.0,0,0,0,0,0,0,0,0,0,0,0,0,0.0,0,0,0.0,0.0,0.0,0,2.586,2.116,b'',0,0,0,b'S 10',0.0,SH.510050,20240207
84528000,0,2.351,0.0,0.0,0.0,0.0,0.0,0.0,0.0,0.0,0.0,0.0,0.0,0.0,0.0,0.0,0,0,0,0,0,0,0,0,0,0,0.0,0.0,0.0,0.0,0.0,0.0,0.0,0.0,0.0,0.0,0,0,0,0,0,0,0,0,0,0,0,0,0.0,0,0,0.0,0.0,0.0,0,2.586,2.116,b'',0,0,0,b'S 10',0.0,SH.510050,20240207
84531000,0,2.351,0.0,0.0,0.0,0.0,0.0,0.0,0.0,0.0,0.0,0.0,0.0,0.0,0.0,0.0,0,0,0,0,0,0,0,0,0,0,0.0,0.0,0.0,0.0,0.0,0.0,0.0,0.0,0.0,0.0,0,0,0,0,0,0,0,0,0,0,0,0,0.0,0,0,0.0,0.0,0.0,0,2.586,2.116,b'',0,0,0,b'S 10',0.0,SH.510050,20240207
84534000,0,2.351,0.0,0.0,0.0,0.0,0.0,0.0,0.0,0.0,0.0,0.0,0.0,0.0,0.0,0.0,0,0,0,0,0,0,0,0,0,0,0.0,0.0,0.0,0.0,0.0,0.0,0.0,0.0,0.0,0.0,0,0,0,0,0,0,0,0,0,0,0,0,0.0,0,0,0.0,0.0,0.0,0,2.586,2.116,b'',0,0,0,b'S 10',0.0,SH.510050,20240207
84537000,0,2.351,0.0,0.0,0.0,0.0,0.0,0.0,0.0,0.0,0.0,0.0,0.0,0.0,0.0,0.0,0,0,0,0,0,0,0,0,0,0,0.0,0.0,0.0,0.0,0.0,0.0,0.0,0.0,0.0,0.0,0,0,0,0,0,0,0,0,0,0,0,0,0.0,0,0,0.0,0.0,0.0,0,2.586,2.116,b'',0,0,0,b'S 10',0.0,SH.510050,20240207
84540000,0,2.351,0.0,0.0,0.0,0.0,0.0,0.0,0.0,0.0,0.0,0.0,0.0,0.0,0.0,0.0,0,0,0,0,0,0,0,0,0,0,0.0,0.0,0.0,0.0,0.0,0.0,0.0,0.0,0.0,0.0,0,0,0,0,0,0,0,0,0,0,0,0,0.0,0,0,0.0,0.0,0.0,0,2.586,2.116,b'',0,0,0,b'S 10',0.0,SH.510050,20240207
84543000,0,2.351,0.0,0.0,0.0,0.0,0.0,0.0,0.0,0.0,0.0,0.0,0.0,0.0,0.0,0.0,0,0,0,0,0,0,0,0,0,0,0.0,0.0,0.0,0.0,0.0,0.0,0.0,0.0,0.0,0.0,0,0,0,0,0,0,0,0,0,0,0,0,0.0,0,0,0.0,0.0,0.0,0,2.586,2.116,b'',0,0,0,b'S 10',0.0,SH.510050,20240207
84546000,0,2.351,0.0,0.0,0.0,0.0,0.0,0.0,0.0,0.0,0.0,0.0,0.0,0.0,0.0,0.0,0,0,0,0,0,0,0,0,0,0,0.0,0.0,0.0,0.0,0.0,0.0,0.0,0.0,0.0,0.0,0,0,0,0,0,0,0,0,0,0,0,0,0.0,0,0,0.0,0.0,0.0,0,2.586,2.116,b'',0,0,0,b'S 10',0.0,SH.510050,20240207
84549000,0,2.351,0.0,0.0,0.0,0.0,0.0,0.0,0.0,0.0,0.0,0.0,0.0,0.0,0.0,0.0,0,0,0,0,0,0,0,0,0,0,0.0,0.0,0.0,0.0,0.0,0.0,0.0,0.0,0.0,0.0,0,0,0,0,0,0,0,0,0,0,0,0,0.0,0,0,0.0,0.0,0.0,0,2.586,2.116,b'',0,0,0,b'S 10',0.0,SH.510050,20240207
84552000,0,2.351,0.0,0.0,0.0,0.0,0.0,0.0,0.0,0.0,0.0,0.0,0.0,0.0,0.0,0.0,0,0,0,0,0,0,0,0,0,0,0.0,0.0,0.0,0.0,0.0,0.0,0.0,0.0,0.0,0.0,0,0,0,0,0,0,0,0,0,0,0,0,0.0,0,0,0.0,0.0,0.0,0,2.586,2.116,b'',0,0,0,b'S 10',0.0,SH.510050,20240207
84555000,0,2.351,0.0,0.0,0.0,0.0,0.0,0.0,0.0,0.0,0.0,0.0,0.0,0.0,0.0,0.0,0,0,0,0,0,0,0,0,0,0,0.0,0.0,0.0,0.0,0.0,0.0,0.0,0.0,0.0,0.0,0,0,0,0,0,0,0,0,0,0,0,0,0.0,0,0,0.0,0.0,0.0,0,2.586,2.116,b'',0,0,0,b'S 10',0.0,SH.510050,20240207
84558000,0,2.351,0.0,0.0,0.0,0.0,0.0,0.0,0.0,0.0,0.0,0.0,0.0,0.0,0.0,0.0,0,0,0,0,0,0,0,0,0,0,0.0,0.0,0.0,0.0,0.0,0.0,0.0,0.0,0.0,0.0,0,0,0,0,0,0,0,0,0,0,0,0,0.0,0,0,0.0,0.0,0.0,0,2.586,2.116,b'',0,0,0,b'S 10',0.0,SH.510050,20240207
84601000,0,2.351,0.0,0.0,0.0,0.0,0.0,0.0,0.0,0.0,0.0,0.0,0.0,0.0,0.0,0.0,0,0,0,0,0,0,0,0,0,0,0.0,0.0,0.0,0.0,0.0,0.0,0.0,0.0,0.0,0.0,0,0,0,0,0,0,0,0,0,0,0,0,0.0,0,0,0.0,0.0,0.0,0,2.586,2.116,b'',0,0,0,b'S 10',0.0,SH.510050,20240207
84604000,0,2.351,0.0,0.0,0.0,0.0,0.0,0.0,0.0,0.0,0.0,0.0,0.0,0.0,0.0,0.0,0,0,0,0,0,0,0,0,0,0,0.0,0.0,0.0,0.0,0.0,0.0,0.0,0.0,0.0,0.0,0,0,0,0,0,0,0,0,0,0,0,0,0.0,0,0,0.0,0.0,0.0,0,2.586,2.116,b'',0,0,0,b'S 10',0.0,SH.510050,20240207
84607000,0,2.351,0.0,0.0,0.0,0.0,0.0,0.0,0.0,0.0,0.0,0.0,0.0,0.0,0.0,0.0,0,0,0,0,0,0,0,0,0,0,0.0,0.0,0.0,0.0,0.0,0.0,0.0,0.0,0.0,0.0,0,0,0,0,0,0,0,0,0,0,0,0,0.0,0,0,0.0,0.0,0.0,0,2.586,2.116,b'',0,0,0,b'S 10',0.0,SH.510050,20240207
84610000,0,2.351,0.0,0.0,0.0,0.0,0.0,0.0,0.0,0.0,0.0,0.0,0.0,0.0,0.0,0.0,0,0,0,0,0,0,0,0,0,0,0.0,0.0,0.0,0.0,0.0,0.0,0.0,0.0,0.0,0.0,0,0,0,0,0,0,0,0,0,0,0,0,0.0,0,0,0.0,0.0,0.0,0,2.586,2.116,b'',0,0,0,b'S 10',0.0,SH.510050,20240207
84613000,0,2.351,0.0,0.0,0.0,0.0,0.0,0.0,0.0,0.0,0.0,0.0,0.0,0.0,0.0,0.0,0,0,0,0,0,0,0,0,0,0,0.0,0.0,0.0,0.0,0.0,0.0,0.0,0.0,0.0,0.0,0,0,0,0,0,0,0,0,0,0,0,0,0.0,0,0,0.0,0.0,0.0,0,2.586,2.116,b'',0,0,0,b'S 10',0.0,SH.510050,20240207
84616000,0,2.351,0.0,0.0,0.0,0.0,0.0,0.0,0.0,0.0,0.0,0.0,0.0,0.0,0.0,0.0,0,0,0,0,0,0,0,0,0,0,0.0,0.0,0.0,0.0,0.0,0.0,0.0,0.0,0.0,0.0,0,0,0,0,0,0,0,0,0,0,0,0,0.0,0,0,0.0,0.0,0.0,0,2.586,2.116,b'',0,0,0,b'S 10',0.0,SH.510050,20240207
84619000,0,2.351,0.0,0.0,0.0,0.0,0.0,0.0,0.0,0.0,0.0,0.0,0.0,0.0,0.0,0.0,0,0,0,0,0,0,0,0,0,0,0.0,0.0,0.0,0.0,0.0,0.0,0.0,0.0,0.0,0.0,0,0,0,0,0,0,0,0,0,0,0,0,0.0,0,0,0.0,0.0,0.0,0,2.586,2.116,b'',0,0,0,b'S 10',0.0,SH.510050,20240207
84622000,0,2.351,0.0,0.0,0.0,0.0,0.0,0.0,0.0,0.0,0.0,0.0,0.0,0.0,0.0,0.0,0,0,0,0,0,0,0,0,0,0,0.0,0.0,0.0,0.0,0.0,0.0,0.0,0.0,0.0,0.0,0,0,0,0,0,0,0,0,0,0,0,0,0.0,0,0,0.0,0.0,0.0,0,2.586,2.116,b'',0,0,0,b'S 10',0.0,SH.510050,20240207
84625000,0,2.351,0.0,0.0,0.0,0.0,0.0,0.0,0.0,0.0,0.0,0.0,0.0,0.0,0.0,0.0,0,0,0,0,0,0,0,0,0,0,0.0,0.0,0.0,0.0,0.0,0.0,0.0,0.0,0.0,0.0,0,0,0,0,0,0,0,0,0,0,0,0,0.0,0,0,0.0,0.0,0.0,0,2.586,2.116,b'',0,0,0,b'S 10',0.0,SH.510050,20240207
84628000,0,2.351,0.0,0.0,0.0,0.0,0.0,0.0,0.0,0.0,0.0,0.0,0.0,0.0,0.0,0.0,0,0,0,0,0,0,0,0,0,0,0.0,0.0,0.0,0.0,0.0,0.0,0.0,0.0,0.0,0.0,0,0,0,0,0,0,0,0,0,0,0,0,0.0,0,0,0.0,0.0,0.0,0,2.586,2.116,b'',0,0,0,b'S 10',0.0,SH.510050,20240207
84631000,0,2.351,0.0,0.0,0.0,0.0,0.0,0.0,0.0,0.0,0.0,0.0,0.0,0.0,0.0,0.0,0,0,0,0,0,0,0,0,0,0,0.0,0.0,0.0,0.0,0.0,0.0,0.0,0.0,0.0,0.0,0,0,0,0,0,0,0,0,0,0,0,0,0.0,0,0,0.0,0.0,0.0,0,2.586,2.116,b'',0,0,0,b'S 10',0.0,SH.510050,20240207
84634000,0,2.351,0.0,0.0,0.0,0.0,0.0,0.0,0.0,0.0,0.0,0.0,0.0,0.0,0.0,0.0,0,0,0,0,0,0,0,0,0,0,0.0,0.0,0.0,0.0,0.0,0.0,0.0,0.0,0.0,0.0,0,0,0,0,0,0,0,0,0,0,0,0,0.0,0,0,0.0,0.0,0.0,0,2.586,2.116,b'',0,0,0,b'S 10',0.0,SH.510050,20240207
84637000,0,2.351,0.0,0.0,0.0,0.0,0.0,0.0,0.0,0.0,0.0,0.0,0.0,0.0,0.0,0.0,0,0,0,0,0,0,0,0,0,0,0.0,0.0,0.0,0.0,0.0,0.0,0.0,0.0,0.0,0.0,0,0,0,0,0,0,0,0,0,0,0,0,0.0,0,0,0.0,0.0,0.0,0,2.586,2.116,b'',0,0,0,b'S 10',0.0,SH.510050,20240207
